[06-May-25 11:44:04 - INFO] - bot - Bot Running..!
[06-May-25 11:44:04 - INFO] - bot - 
Links Sharing Started

[06-May-25 11:44:18 - ERROR] - pyrogram.dispatcher - Unhandled exception: cannot open /etc/resolv.conf
Traceback (most recent call last):
  File "/data/data/com.termux/files/usr/lib/python3.12/site-packages/pyrogram/dispatcher.py", line 370, in _process_packet
    await self._execute_callback(handler, parsed_update)
  File "/data/data/com.termux/files/usr/lib/python3.12/site-packages/pyrogram/dispatcher.py", line 407, in _execute_callback
    await handler.callback(self.client, *args)
  File "/data/data/com.termux/files/usr/lib/python3.12/site-packages/pyrogram/handlers/message_handler.py", line 154, in resolve_future_or_callback
    await self.original_callback(client, message, *args)
  File "/data/data/com.termux/files/home/downloads/links-bot-v2/plugins/start.py", line 35, in start_command
    await add_user(user_id)  # Add user to DB
    ^^^^^^^^^^^^^^^^^^^^^^^
  File "/data/data/com.termux/files/home/downloads/links-bot-v2/database/database.py", line 14, in add_user
    existing_user = await user_data.find_one({'_id': user_id})
                    ^^^^^^^^^^^^^^^^^^^^^^^^^^^^^^^^^^^^^^^^^^
  File "/data/data/com.termux/files/usr/lib/python3.12/concurrent/futures/thread.py", line 59, in run
    result = self.fn(*self.args, **self.kwargs)
             ^^^^^^^^^^^^^^^^^^^^^^^^^^^^^^^^^^
  File "/data/data/com.termux/files/usr/lib/python3.12/site-packages/pymongo/synchronous/collection.py", line 1755, in find_one
    for result in cursor.limit(-1):
                  ^^^^^^^^^^^^^^^^
  File "/data/data/com.termux/files/usr/lib/python3.12/site-packages/pymongo/synchronous/cursor.py", line 1284, in __next__
    return self.next()
           ^^^^^^^^^^^
  File "/data/data/com.termux/files/usr/lib/python3.12/site-packages/pymongo/synchronous/cursor.py", line 1260, in next
    if len(self._data) or self._refresh():
                          ^^^^^^^^^^^^^^^
  File "/data/data/com.termux/files/usr/lib/python3.12/site-packages/pymongo/synchronous/cursor.py", line 1208, in _refresh
    self._send_message(q)
  File "/data/data/com.termux/files/usr/lib/python3.12/site-packages/pymongo/synchronous/cursor.py", line 1102, in _send_message
    response = client._run_operation(
               ^^^^^^^^^^^^^^^^^^^^^^
  File "/data/data/com.termux/files/usr/lib/python3.12/site-packages/pymongo/_csot.py", line 119, in csot_wrapper
    return func(self, *args, **kwargs)
           ^^^^^^^^^^^^^^^^^^^^^^^^^^^
  File "/data/data/com.termux/files/usr/lib/python3.12/site-packages/pymongo/synchronous/mongo_client.py", line 1917, in _run_operation
    return self._retryable_read(
           ^^^^^^^^^^^^^^^^^^^^^
  File "/data/data/com.termux/files/usr/lib/python3.12/site-packages/pymongo/synchronous/mongo_client.py", line 2026, in _retryable_read
    return self._retry_internal(
           ^^^^^^^^^^^^^^^^^^^^^
  File "/data/data/com.termux/files/usr/lib/python3.12/site-packages/pymongo/_csot.py", line 119, in csot_wrapper
    return func(self, *args, **kwargs)
           ^^^^^^^^^^^^^^^^^^^^^^^^^^^
  File "/data/data/com.termux/files/usr/lib/python3.12/site-packages/pymongo/synchronous/mongo_client.py", line 1993, in _retry_internal
    ).run()
      ^^^^^
  File "/data/data/com.termux/files/usr/lib/python3.12/site-packages/pymongo/synchronous/mongo_client.py", line 2730, in run
    return self._read() if self._is_read else self._write()
           ^^^^^^^^^^^^
  File "/data/data/com.termux/files/usr/lib/python3.12/site-packages/pymongo/synchronous/mongo_client.py", line 2875, in _read
    self._server = self._get_server()
                   ^^^^^^^^^^^^^^^^^^
  File "/data/data/com.termux/files/usr/lib/python3.12/site-packages/pymongo/synchronous/mongo_client.py", line 2823, in _get_server
    return self._client._select_server(
           ^^^^^^^^^^^^^^^^^^^^^^^^^^^^
  File "/data/data/com.termux/files/usr/lib/python3.12/site-packages/pymongo/synchronous/mongo_client.py", line 1799, in _select_server
    topology = self._get_topology()
               ^^^^^^^^^^^^^^^^^^^^
  File "/data/data/com.termux/files/usr/lib/python3.12/site-packages/pymongo/synchronous/mongo_client.py", line 1737, in _get_topology
    self._resolve_srv()
  File "/data/data/com.termux/files/usr/lib/python3.12/site-packages/pymongo/synchronous/mongo_client.py", line 903, in _resolve_srv
    res = uri_parser._parse_srv(
          ^^^^^^^^^^^^^^^^^^^^^^
  File "/data/data/com.termux/files/usr/lib/python3.12/site-packages/pymongo/synchronous/uri_parser.py", line 163, in _parse_srv
    nodes = dns_resolver.get_hosts()
            ^^^^^^^^^^^^^^^^^^^^^^^^
  File "/data/data/com.termux/files/usr/lib/python3.12/site-packages/pymongo/synchronous/srv_resolver.py", line 157, in get_hosts
    _, nodes = self._get_srv_response_and_hosts(True)
               ^^^^^^^^^^^^^^^^^^^^^^^^^^^^^^^^^^^^^^
  File "/data/data/com.termux/files/usr/lib/python3.12/site-packages/pymongo/synchronous/srv_resolver.py", line 131, in _get_srv_response_and_hosts
    results = self._resolve_uri(encapsulate_errors)
              ^^^^^^^^^^^^^^^^^^^^^^^^^^^^^^^^^^^^^
  File "/data/data/com.termux/files/usr/lib/python3.12/site-packages/pymongo/synchronous/srv_resolver.py", line 125, in _resolve_uri
    raise ConfigurationError(str(exc)) from None
pymongo.errors.ConfigurationError: cannot open /etc/resolv.conf
[06-May-25 11:47:44 - INFO] - root - Stop signal received (SIGINT). Exiting...
[06-May-25 11:47:44 - INFO] - bot - Bot stopped.
[06-May-25 11:48:14 - INFO] - bot - Bot Running..!
[06-May-25 11:48:14 - INFO] - bot - 
Links Sharing Started

[06-May-25 11:52:24 - INFO] - root - Stop signal received (SIGINT). Exiting...
[06-May-25 11:52:28 - INFO] - bot - Bot stopped.
[06-May-25 11:52:57 - INFO] - bot - Bot Running..!
[06-May-25 11:52:57 - INFO] - bot - 
Links Sharing Started

[06-May-25 12:02:58 - WARNING] - pyrogram.connection.connection - Unable to connect due to network issues: Connection timed out
[06-May-25 12:04:27 - WARNING] - pyrogram.connection.connection - Unable to connect due to network issues: Connection timed out
[06-May-25 12:04:32 - INFO] - root - Stop signal received (SIGINT). Exiting...
[06-May-25 12:04:38 - WARNING] - pyrogram.connection.connection - Unable to connect due to network issues: Connection timed out
[06-May-25 12:04:38 - INFO] - bot - Bot stopped.
